<?xml version="1.0"?>
<robot name="platformbot">

    <link name="base_footprint">
   <visual>
      <origin xyz="0 0 0" rpy="0 0 0" />
      <geometry>
        <box size="0.001 0.001 0.001" />
      </geometry>
    </visual>
  </link>

  <joint name="base_link_joint" type="fixed">
    <origin xyz="0.0 0 0.05" rpy="0 0 0" />
    <parent link="base_footprint"/>
    <child link="base_link" />
  </joint>

  
	<link name="base_link">
    <visual>
      <geometry>
        <box size="0.292 0.227 0.0925"/>
      </geometry>
      <material name="silver">
        <color rgba="1.0 0.0 0.0 1"/>
      </material>
    </visual>
    <collision>
      <geometry>
        <box size="0.227 0.292 0.0925"/>
      </geometry>
    </collision>
    <inertial>
      <mass value="8.6"/>
      <inertia ixx="0.067238" iyy="0.043061" izz="0.098035" ixy="0" ixz="0" iyz="0"/>
    </inertial>
  </link>




	<link name="front_box">
    <visual>
      <geometry>
        <box size="0.231 0.1025 0.0925"/>
      </geometry>
      <material name="silver"/>
    </visual>
    <collision>
      <geometry>
        <box size="0.1025 0.231 0.0925"/>
      </geometry>
    </collision>
    <inertial>
      <mass value="3"/>
      <inertia ixx="0.015967" iyy="0.004766" izz="0.015967" ixy="0" ixz="0" iyz="0"/>
    </inertial>
  </link>

  <joint name="front_joint" type="fixed">
    <axis xyz="0 1 0"/>
    <parent link="base_link"/>
    <child link="front_box"/>
    <origin rpy="0 0 0" xyz="0 0.16475 0"/>
  </joint>



	<link name="back_box">
    <visual>
      <geometry>
        <box size="0.231 0.1025 0.0925"/>
      </geometry>
      <material name="silver"/>
    </visual>
    <collision>
      <geometry>
        <box size="0.1025 0.231 0.0925"/>
      </geometry>
    </collision>
    <inertial>
      <mass value="3"/>
      <inertia ixx="0.015967" iyy="0.004766" izz="0.015967" ixy="0" ixz="0" iyz="0"/>
    </inertial>
  </link>

  <joint name="back_joint" type="fixed">
    <axis xyz="0 1 0"/>
    <parent link="base_link"/>
    <child link="back_box"/>
    <origin rpy="0 0 0" xyz="0 -0.16475 0"/>
  </joint>




	<link name="mounting_base">
    <visual>
      <geometry>
        <box size="0.120 0.120 0.065"/>
      </geometry>
      <material name="silver"/>
    </visual>
    <collision>
      <geometry>
        <box size="0.120 0.120 0.065"/>
      </geometry>
    </collision>
    <inertial>
      <mass value="3"/>
      <inertia ixx="0.00395148" iyy="0.00395148" izz="0.006110208" ixy="0" ixz="0" iyz="0"/>
    </inertial>
  </link>

  <joint name="mounting_base_joint" type="fixed">
    <axis xyz="0 0 1"/>
    <parent link="base_link"/>
    <child link="mounting_base"/>
    <origin rpy="0 0 0" xyz="0 0 0.0775"/>
  </joint>




	<link name="lift">
    <visual>
      <geometry>
        <box size="0.08 0.08 1.9"/>
      </geometry>
      <material name="silver"/>
    </visual>
    <collision>
      <geometry>
        <box size="0.08 0.08 1.9"/>
      </geometry>
    </collision>
    <inertial>
      <mass value="5"/>
      <inertia ixx="1.5068333" iyy="1.5068333" izz="0.0053333" ixy="0" ixz="0" iyz="0"/>
    </inertial>
  </link>

  <joint name="lift_joint" type="fixed">
    <axis xyz="0 0 1"/>
    <parent link="mounting_base"/>
    <child link="lift"/>
    <origin rpy="0 0 0" xyz="0 0 0.9825"/>
  </joint>




	<link name="slider">
    <visual>
      <geometry>
        <box size="0.02 0.08 0.15"/>
      </geometry>
      <material name="silver"/>
    </visual>
    <collision>
      <geometry>
        <box size="0.02 0.08 0.15"/>
      </geometry>
    </collision>
    <inertial>
      <mass value="0.6528"/>
      <inertia ixx="0.00157216" iyy="0.00124576" izz="0.00036992" ixy="0" ixz="0" iyz="0"/>
    </inertial>
  </link>

  <joint name="slider_joint" type="prismatic">
    <axis xyz="0 0 1"/>
    <parent link="lift"/>
    <child link="slider"/>
    <origin rpy="0 0 0" xyz="0.05 0 -0.855"/>
		<limit lower="0" upper="1.73" effort="20000.0" velocity="0.02" />
		<dynamics damping="100.0" />
  </joint>




	<link name="horizontal_beam">
    <visual>
      <geometry>
        <box size="0.1 0.08 0.01"/>
      </geometry>
      <material name="silver"/>
    </visual>
    <collision>
      <geometry>
        <box size="0.1 0.08 0.01"/>
      </geometry>
    </collision>
    <inertial>
      <mass value="0.2176"/>
      <inertia ixx="0.000117867" iyy="0.000183147" izz="0.000297387" ixy="0" ixz="0" iyz="0"/>
    </inertial>
  </link>

  <joint name="horizontal_beam_joint" type="fixed">
    <axis xyz="1 0 1"/>
    <parent link="slider"/>
    <child link="horizontal_beam"/>
    <origin rpy="0 0 0" xyz="0.06 0 -0.07"/>
  </joint>




	<link name="vertical_beam">
    <visual>
      <geometry>
        <box size="0.01 0.08 0.2"/>
      </geometry>
      <material name="silver"/>
    </visual>
    <collision>
      <geometry>
        <box size="0.01 0.08 0.2"/>
      </geometry>
    </collision>
    <inertial>
      <mass value="0.4352"/>
      <inertia ixx="0.001682773" iyy="0.001454293" izz="0.000235733" ixy="0" ixz="0" iyz="0"/>
    </inertial>
  </link>

  <joint name="vertical_beam_joint" type="fixed">
    <axis xyz="1 0 1"/>
    <parent link="horizontal_beam"/>
    <child link="vertical_beam"/>
    <origin rpy="0 0 0" xyz="0.045 0 -0.105"/>
  </joint>



	<link name="key_holder">
    <visual>
      <geometry>
        <box size="0.05 0.08 0.01"/>
      </geometry>
      <material name="silver"/>
    </visual>
    <collision>
      <geometry>
        <box size="0.05 0.08 0.01"/>
      </geometry>
    </collision>
    <inertial>
      <mass value="0.4352"/>
      <inertia ixx="0.000058933" iyy="0.000023573" izz="0.000080693" ixy="0" ixz="0" iyz="0"/>
    </inertial>
  </link>

  <joint name="key_holder_joint" type="fixed">
    <axis xyz="1 0 1"/>
    <parent link="vertical_beam"/>
    <child link="key_holder"/>
    <origin rpy="0 0 0" xyz="0.030 0 -0.095"/>
  </joint>




	<link name="front_right_wheel">
    <inertial>
      <origin xyz="1 1 1" rpy="0 0 0" />
      <mass value="0.35" />
      <inertia ixx="0.000295835" iyy="0.000451612" izz="0.000295835" ixy="0" ixz="0" iyz="0"/>
    </inertial>
    <visual>
      <origin xyz="0 0 0" rpy="0 0 0" />
      <geometry>
	<mesh filename="package://mecanum_bot/urdf/wheel.STL" />
      </geometry>
      <material name="">
        <color rgba="0.5 0.5 0.5 1" />
      </material>
    </visual>
    <collision>
      <origin xyz="0 0 0" rpy="0 0 0" />
      <geometry>
      </geometry>
    </collision>
  </link>

	<joint name="front_right_wheel_joint" type="fixed">
    <axis xyz="0 0 1"/>
    <parent link="base_link"/>
    <child link="front_right_wheel"/>
    <origin rpy="0 0 -3.1415926" xyz="-0.12 0.1742 -.0178"/>
  </joint>




	<link name="front_left_wheel">
    <inertial>
      <origin xyz="1 1 1" rpy="0 0 0" />
      <mass value="0.35" />
      <inertia ixx="0.000295835" iyy="0.000451612" izz="0.000295835" ixy="0" ixz="0" iyz="0"/>
    </inertial>
    <visual>
      <origin xyz="0 0 0" rpy="0 0 0" />
      <geometry>
	<mesh filename="package://mecanum_bot/urdf/wheel.STL" />
      </geometry>
      <material name="">
        <color rgba="0.5 0.5 0.5 1" />
      </material>
    </visual>
   <collision>
      <origin xyz="0 0 0" rpy="0 0 0" />
      <geometry>
      </geometry>
    </collision>
  </link>
  

	<joint name="front_left_wheel_joint" type="fixed">
    <axis xyz="1 0 0"/>
    <parent link="base_link"/>
    <child link="front_left_wheel"/>
    <origin rpy="0 0 0" xyz="0.12 0.1742 -.0178"/>
  </joint>





	<link name="back_right_wheel">
    <inertial>
      <origin xyz="1 1 1" rpy="0 0 0" />
      <mass value="0.35" />
      <inertia ixx="0.000295835" iyy="0.000451612" izz="0.000295835" ixy="0" ixz="0" iyz="0"/>
    </inertial>
    <visual>
      <origin xyz="0 0 0" rpy="0 0 0" />
      <geometry>
	<mesh filename="package://mecanum_bot/urdf/wheel.STL" />
      </geometry>
      <material name="">
        <color rgba="0.5 0.5 0.5 1" />
      </material>
    </visual>
    <collision>
      <origin xyz="0 0 0" rpy="0 0 0" />
      <geometry>
      </geometry>
    </collision>
  </link>

	<joint name="back_right_wheel_joint" type="fixed">
    <axis xyz="1 0 0"/>
    <parent link="base_link"/>
    <child link="back_right_wheel"/>
    <origin rpy="0 0 -3.1415926" xyz="-0.12 -0.1742 -.0178"/>
  </joint>




	<link name="back_left_wheel">
    <inertial>
      <origin xyz="1 1 1" rpy="0 0 0" />
      <mass value="0.35" />
      <inertia ixx="0.000295835" iyy="0.000451612" izz="0.000295835" ixy="0" ixz="0" iyz="0"/>
    </inertial>
    <visual>
      <origin xyz="0 0 0" rpy="0 0 0" />
      <geometry>
	<mesh filename="package://mecanum_bot/urdf/wheel.STL" />
      </geometry>
      <material name="">
        <color rgba="1 0.5 0.5 1" />
      </material>
    </visual>
    <collision>
      <origin xyz="0 0 0" rpy="0 0 0" />
      <geometry>
      </geometry>
    </collision>
  </link>

	<joint name="back_left_wheel_joint" type="fixed">
    <axis xyz="0 0 1"/>
    <parent link="base_link"/>
    <child link="back_left_wheel"/>
    <origin rpy="0 0 0" xyz="0.12 -0.1742 -.0178"/>
  </joint>





<link name="beacon_1">
  <visual>
    <geometry>
      <box size= "0.055 0.055 0.033"/>
    </geometry>
  </visual>
</link>




<link name="beacon_2">
  <visual>
    <geometry>
      
      <box size= "0.055 0.055 0.033"/>
    </geometry>
  </visual>
</link>



<joint name = "beacon_1_joint" type="fixed">
    <parent link="lift"/>
    <child link="beacon_1" />
    <origin xyz="0 0 0.9665" rpy="0 0 0" />	
</joint>



<joint name = "beacon_2_joint" type="fixed">
    <parent link="base_link"/>
    <child link="beacon_2" />
    <origin xyz="0 -0.1885 0.06275" rpy="0 0 0" />	
</joint>




  <gazebo reference="beacon_1">
    <material>Gazebo/Orange</material>
  </gazebo>

  <gazebo reference="beacon_2">
    <material>Gazebo/Orange</material>
  </gazebo>





	<link name="back_right_wheel_sp">
    <visual>
      <geometry>
        <cylinder length="0.001" radius="0.001"/>
      </geometry>
    </visual>

    <collision>
      <geometry>
        <sphere radius="0.0508"/>
      </geometry>
    </collision>

    <inertial>
      <mass value="0.35"/>
      <inertia ixx="0.000295835" iyy="0.000451612" izz="0.000295835" ixy="0" ixz="0" iyz="0"/>
    </inertial>
  </link>

  <joint name="back_right_wheel_joint_sp" type="continuous">
    <axis xyz="0 0 1"/>
    <parent link="base_link"/>
    <child link="back_right_wheel_sp"/>
    <origin rpy="-1.5708 0 1.5708" xyz="-0.142 -0.1742 -.0178"/>
  </joint>



  <link name="front_right_wheel_sp">
    <visual>
      <geometry>
        <cylinder length="0.001" radius="0.001"/>
      </geometry>
    </visual>

    <collision>
      <geometry>
        <sphere radius="0.0508"/>
      </geometry>
    </collision>

    <inertial>
     	<mass value="0.35"/>
      <inertia ixx="0.000295835" iyy="0.000451612" izz="0.000295835" ixy="0" ixz="0" iyz="0"/>
    </inertial>
  </link>

  <joint name="front_right_wheel_joint_sp" type="continuous">
    <axis xyz="0 0 1"/>
    <parent link="base_link"/>
    <child link="front_right_wheel_sp"/>
    <origin rpy="-1.5708 0 1.5708" xyz="-0.142 0.1742 -.0178"/>
  </joint>



  <link name="back_left_wheel_sp">
    <visual>
      <geometry>
        <cylinder length="0.001" radius="0.001"/>
      </geometry>
      <material name="black"/>
    </visual>

    <collision>
      <geometry>
        <sphere radius="0.0508"/>
      </geometry>
    </collision>

    <inertial>
      <mass value="0.35"/>
      <inertia ixx="0.000295835" iyy="0.000451612" izz="0.000295835" ixy="0" ixz="0" iyz="0"/>
    </inertial>
  </link>

  <joint name="back_left_wheel_joint_sp" type="continuous">
    <axis xyz="0 0 1"/>
    <parent link="base_link"/>
    <child link="back_left_wheel_sp"/>
    <origin rpy="-1.5708 0 1.5708" xyz="0.142 -0.1742 -.0178"/>
  </joint>



	<link name="front_left_wheel_sp">
    <visual>
      <geometry>
        <cylinder length="0.001" radius="0.001"/>
      </geometry>
      <material name="black"/>
    </visual>
  

    <collision>
      <geometry>
        <sphere radius="0.0508"/>
      </geometry>
    </collision>

    <inertial>
      <mass value="0.35"/>
      <inertia ixx="0.000295835" iyy="0.000451612" izz="0.000295835" ixy="0" ixz="0" iyz="0"/>
    </inertial>
  </link>

  <joint name="front_left_wheel_joint_sp" type="continuous">
    <axis xyz="0 0 1"/>
    <parent link="base_link"/>
    <child link="front_left_wheel_sp"/>
    <origin rpy="-1.5708 0 1.5708" xyz="0.142 0.1742 -.0178"/>
  </joint>








	<gazebo>
    <plugin name="object_controller" filename="libgazebo_ros_force_based_move.so">
      <commandTopic>cmd_vel</commandTopic>
      <odometryTopic>odom</odometryTopic>
      <odometryFrame>odom</odometryFrame>
      <odometryRate>20.0</odometryRate>
      <robotBaseFrame>base_footprint</robotBaseFrame>
    </plugin>
  </gazebo>





</robot>

