<?xml version="1.0"?>
<robot name="wall_e_lid">

#TODO: dimensions of the body

	<link name="base_footprint">
		<visual>
      			<origin xyz="0 0 0" rpy="0 0 0" />
      			<geometry>
        			<box size="0.001 0.001 0.001" />
      			</geometry>
    		</visual>
  	</link>

	  <joint name="base_link_joint" type="fixed">
    		<origin xyz="0 0 0" rpy="0 0 0" />
    		<parent link="base_footprint"/>
		<child link="base_link" />
	  </joint>

	<link name="base_link">
		<visual>
			<geometry>
				<box size="0.194 0.122 0.056"/>
			</geometry>
			<material name="red"/>
		</visual>

		<collision>
			<geometry>
				<box size="0.194 0.122 0.056"/>
			</geometry>
		</collision>

		<inertial>
			<mass value="1"/>
			<inertia ixx="0.001501" iyy="0.069444" izz="0.003976" ixy="0" ixz="0" iyz="0"/>
		</inertial>

	</link>

	<link name="left_front_wheel">
		<visual>
			<geometry>
				<cylinder length="0.026" radius="0.032"/>
			</geometry>
			<origin rpy="1.57075 0 0" xyz="0 0 0"/>
			<material name="black"/>
		</visual>

		<collision>
			<geometry>
				<cylinder length="0.026" radius="0.032"/>
			</geometry>
			<origin rpy="1.57075 0 0" xyz="0 0 0"/>
		</collision>

		<inertial>
      			<mass value="0.35" />
      			<inertia ixx="0.000295835" iyy="0.000451612" izz="0.000295835" ixy="0" ixz="0" iyz="0"/>
    		</inertial>

	</link>

	<joint name="base_to_lf_wheel" type="continuous">
		<axis rpy="0 0 0" xyz="0 1 0"/>
		<parent link="base_link"/>
		<child link="left_front_wheel"/>
		<origin rpy="0 0 0" xyz="0.065 0.074 -0.017"/>
	</joint>

	<link name="right_front_wheel">
                <visual>
                        <geometry>
                                <cylinder length="0.026" radius="0.032"/>
                        </geometry>
                        <origin rpy="1.57075 0 0" xyz="0 0 0"/>
			<material name="black"/>
                </visual>

		<collision>
			<geometry>
				<cylinder length="0.026" radius="0.032"/>
			</geometry>
			<origin rpy="1.57075 0 0" xyz="0 0 0"/>
		</collision>

		<inertial>
      			<mass value="0.35" />
      			<inertia ixx="0.000295835" iyy="0.000451612" izz="0.000295835" ixy="0" ixz="0" iyz="0"/>
    		</inertial>
        </link>

        <joint name="base_to_rf_wheel" type="continuous">
		<axis rpy="0 0 0" xyz="0 1 0"/>
                <parent link="base_link"/>
                <child link="right_front_wheel"/>
                <origin rpy="0 0 0" xyz="0.065 -0.074 -0.017"/>
        </joint>

	<link name="left_back_wheel">
                <visual>
                        <geometry>
                                <cylinder length="0.026" radius="0.032"/>
                        </geometry>
                        <origin rpy="1.57075 0 0" xyz="0 0 0"/>
			<material name="black"/>
                </visual>

		<collision>
			<geometry>
				<cylinder length="0.026" radius="0.032"/>
			</geometry>
			<origin rpy="1.57075 0 0" xyz="0 0 0"/>
		</collision>

		<inertial>
      			<mass value="0.35" />
      			<inertia ixx="0.000295835" iyy="0.000451612" izz="0.000295835" ixy="0" ixz="0" iyz="0"/>
    		</inertial>
        </link>

        <joint name="base_to_lb_wheel" type="continuous">
                <axis rpy="0 0 0" xyz="0 1 0"/>
                <parent link="base_link"/>
                <child link="left_back_wheel"/>
                <origin rpy="0 0 0" xyz="-0.065 0.074 -0.017"/>
        </joint>

	<link name="right_back_wheel">
                <visual>
                        <geometry>
                                <cylinder length="0.026" radius="0.032"/>
                        </geometry>
                        <origin rpy="1.57075 0 0" xyz="0 0 0"/>
			<material name="black"/>
                </visual>

		<collision>
			<geometry>
				<cylinder length="0.026" radius="0.032"/>
			</geometry>
			<origin rpy="1.57075 0 0" xyz="0 0 0"/>
		</collision>

		<inertial>
      			<mass value="0.35" />
      			<inertia ixx="0.000295835" iyy="0.000451612" izz="0.000295835" ixy="0" ixz="0" iyz="0"/>
    		</inertial>
        </link>

        <joint name="base_to_rb_wheel" type="continuous">
                <axis rpy="0 0 0" xyz="0 1 0"/>
                <parent link="base_link"/>
                <child link="right_back_wheel"/>
                <origin rpy="0 0 0" xyz="-0.065 -0.074 -0.017"/>
        </joint>

	<link name="body">
		<visual>
			<geometry>
				<box size="0.2 0.174 0.01"/>
			</geometry>
			<material name="red"/>
		</visual>

		<collision>
			<geometry>
				<box size="0.2 0.174 0.01"/>
			</geometry>
		</collision>
	</link>

	<joint name="base_to_body" type="fixed">
		<parent link="base_link"/>
		<child link="body"/>
		<origin rpy="0 0 0" xyz="0 0 0.033"/>
	</joint>



         <link name="hokuyo_link" type="laser">
 <inertial>
      <mass value="1e-5" />
      <origin xyz="0 0 0" rpy="0 0 0"/>
      <inertia ixx="1e-6" ixy="0" ixz="0" iyy="1e-6" iyz="0" izz="1e-6" />
    </inertial>
     <visual>
       <origin xyz="0 0 0" rpy="0 0 0"/>
       <geometry>
         <cylinder length="0.1" radius="0.05" />
       </geometry>
     </visual>
     <collision>
      <origin xyz="0 0 0" rpy="0 0 0"/>
       <geometry>
         <cylinder length="0.1" radius="0.05" />
       </geometry>
     </collision>
  </link>

<joint name="hokuyo_link" type="fixed">
  <origin xyz="0 0 0.05" rpy="0 0 0" />
  <parent link="base_link" />
  <child link="hokuyo_link"/>
</joint>

   <gazebo reference="hokuyo_link">
    <sensor type="ray" name="head_hokuyo_sensor">
      <pose>0 0 0 0 0 0</pose>
      <visualize>true</visualize>
      <update_rate>40</update_rate>
      <ray>
        <scan>
          <horizontal>
            <samples>8</samples>
            <resolution>1</resolution>
            <min_angle>0</min_angle>
            <max_angle>5.497787144</max_angle>


          </horizontal>
        </scan>
        <range>
          <min>0.1</min>
          <max>30.0</max>
          <resolution>0.01</resolution>
        </range>
        <noise>
          <type>gaussian</type>
          <!-- Noise parameters based on published spec for Hokuyo laser
               achieving "+-30mm" accuracy at range < 10m.  A mean of 0.0m and
               stddev of 0.01m will put 99.7% of samples within 0.03m of the true
               reading. -->
          <mean>0.0</mean>
          <stddev>0.01</stddev>
        </noise>
      </ray>
      <plugin name="gazebo_ros_head_hokuyo_controller" filename="libgazebo_ros_laser.so">
        <topicName>/laser/scanLidar</topicName>
        <frameName>hokuyo_link</frameName>
      </plugin>
    </sensor>
  </gazebo>



	<gazebo>
		<plugin name="skid_steer_drive_controller" filename="libgazebo_ros_skid_steer_drive.so">
			<updateRate>100.0</updateRate>
    			<robotNamespace>/</robotNamespace>
    			<leftFrontJoint>base_to_lf_wheel</leftFrontJoint>
    			<rightFrontJoint>base_to_rf_wheel</rightFrontJoint>
    			<leftRearJoint>base_to_lb_wheel</leftRearJoint>
    			<rightRearJoint>base_to_rb_wheel</rightRearJoint>
   		 	<wheelSeparation>0.4</wheelSeparation>
    			<wheelDiameter>0.064</wheelDiameter>
 			<robotBaseFrame>base_link</robotBaseFrame>
    			<torque>20</torque>
    			<topicName>cmd_vel</topicName>
    			<broadcastTF>true</broadcastTF>
  		</plugin>
	</gazebo>
</robot>
