<?xml version="1.0"?>
<robot name="legion">

#TODO: dimensions of the body

	<link name="base_footprint">
		<visual>
      			<origin xyz="0 0 0" rpy="0 0 0" />
      			<geometry>
        			<box size="0.001 0.001 0.001" />
      			</geometry>
    		</visual>
  	</link>

	  <joint name="base_link_joint" type="fixed">
    		<origin xyz="0 0 0" rpy="0 0 0" />
    		<parent link="base_footprint"/>
		<child link="base_link" />
	  </joint>

	<link name="base_link">
		<visual>
			<geometry>
				<box size="0.194 0.122 0.056"/>
			</geometry>
			<material name="red"/>
		</visual>

		<collision>
			<geometry>
				<box size="0.194 0.122 0.056"/>
			</geometry>
		</collision>
		
		<inertial>
			<mass value="1"/>
			<inertia ixx="0.001501" iyy="0.069444" izz="0.003976" ixy="0" ixz="0" iyz="0"/>
		</inertial>
				
	</link>

	<link name="left_front_wheel">
		<visual>
			<geometry>
				<cylinder length="0.026" radius="0.032"/>
			</geometry>
			<origin rpy="1.57075 0 0" xyz="0 0 0"/>
			<material name="black"/>
		</visual>

		<collision>
			<geometry>
				<cylinder length="0.026" radius="0.032"/>
			</geometry>
			<origin rpy="1.57075 0 0" xyz="0 0 0"/>
		</collision>

		<inertial>
      			<mass value="0.35" />
      			<inertia ixx="0.000295835" iyy="0.000451612" izz="0.000295835" ixy="0" ixz="0" iyz="0"/>
    		</inertial>
			
	</link>

	<joint name="base_to_lf_wheel" type="continuous">
		<axis rpy="0 0 0" xyz="0 1 0"/>
		<parent link="base_link"/>
		<child link="left_front_wheel"/>
		<origin rpy="0 0 0" xyz="0.065 0.074 -0.017"/>
	</joint>
	
	<link name="right_front_wheel">
                <visual>
                        <geometry>
                                <cylinder length="0.026" radius="0.032"/>
                        </geometry>
                        <origin rpy="1.57075 0 0" xyz="0 0 0"/>
			<material name="black"/>
                </visual>

		<collision>
			<geometry>
				<cylinder length="0.026" radius="0.032"/>
			</geometry>
			<origin rpy="1.57075 0 0" xyz="0 0 0"/>
		</collision>

		<inertial>
      			<mass value="0.35" />
      			<inertia ixx="0.000295835" iyy="0.000451612" izz="0.000295835" ixy="0" ixz="0" iyz="0"/>
    		</inertial>
        </link>

        <joint name="base_to_rf_wheel" type="continuous">
		<axis rpy="0 0 0" xyz="0 1 0"/>
                <parent link="base_link"/>
                <child link="right_front_wheel"/>
                <origin rpy="0 0 0" xyz="0.065 -0.074 -0.017"/>
        </joint>
	
	<link name="left_back_wheel">
                <visual>
                        <geometry>
                                <cylinder length="0.026" radius="0.032"/>
                        </geometry>
                        <origin rpy="1.57075 0 0" xyz="0 0 0"/>
			<material name="black"/>
                </visual>

		<collision>
			<geometry>
				<cylinder length="0.026" radius="0.032"/>
			</geometry>
			<origin rpy="1.57075 0 0" xyz="0 0 0"/>
		</collision>

		<inertial>
      			<mass value="0.35" />
      			<inertia ixx="0.000295835" iyy="0.000451612" izz="0.000295835" ixy="0" ixz="0" iyz="0"/>
    		</inertial>
        </link>

        <joint name="base_to_lb_wheel" type="continuous">
                <axis rpy="0 0 0" xyz="0 1 0"/>
                <parent link="base_link"/>
                <child link="left_back_wheel"/>
                <origin rpy="0 0 0" xyz="-0.065 0.074 -0.017"/>
        </joint>
	
	<link name="right_back_wheel">
                <visual>
                        <geometry>
                                <cylinder length="0.026" radius="0.032"/>
                        </geometry>
                        <origin rpy="1.57075 0 0" xyz="0 0 0"/>
			<material name="black"/>
                </visual>

		<collision>
			<geometry>
				<cylinder length="0.026" radius="0.032"/>
			</geometry>
			<origin rpy="1.57075 0 0" xyz="0 0 0"/>
		</collision>

		<inertial>
      			<mass value="0.35" />
      			<inertia ixx="0.000295835" iyy="0.000451612" izz="0.000295835" ixy="0" ixz="0" iyz="0"/>
    		</inertial>
        </link>

        <joint name="base_to_rb_wheel" type="continuous">
                <axis rpy="0 0 0" xyz="0 1 0"/>
                <parent link="base_link"/>
                <child link="right_back_wheel"/>
                <origin rpy="0 0 0" xyz="-0.065 -0.074 -0.017"/>
        </joint>
	
	<link name="body">
		<visual>
			<geometry>
				<box size="0.2 0.174 0.01"/>
			</geometry>
			<material name="red"/>
		</visual>

		<collision>
			<geometry>
				<box size="0.2 0.174 0.01"/>
			</geometry>
		</collision>
	</link>

	<joint name="base_to_body" type="fixed">
		<parent link="base_link"/>
		<child link="body"/>
		<origin rpy="0 0 0" xyz="0 0 0.033"/>
	</joint>

        <!-- central front ------------------------------------------------------------------ -->
        
	<joint name="cf_sensor" type="fixed">
                <axis xyz="0 1 0" />
                <origin xyz="0.1 0 0.005" rpy="0 0 0"/>
                <parent link="body"/>
                <child link="cf_sensor_link"/>
        </joint>
	
	<link name="cf_sensor_link">
                <collision>
                        <origin xyz="0 0 0" rpy="0 0 0"/>
                        <geometry>
                                <box size="0.1 0.1 0.1"/>
                        </geometry>
                </collision>
                
        	<inertial>
                	<mass value="1e-5" />
                	<origin xyz="0 0 0" rpy="0 0 0"/>
               		<inertia ixx="1e-6" ixy="0" ixz="0" iyy="1e-6" iyz="0" izz="1e-6" />
        	</inertial>
        </link>

        <gazebo reference="cf_sensor_link">
    		<sensor type="ray" name='cf_sensor'>
      			<pose>0 0 0 0 0 0</pose>
      			<visualize>true</visualize>
      			<update_rate>40</update_rate>
      			<ray>
        			<scan>
          				<horizontal>
            					<samples>720</samples>
            					<resolution>1</resolution>
            					<min_angle>-0.4</min_angle>
            					<max_angle>0.4</max_angle>
          				</horizontal>
        			</scan>
       				<range>
          				<min>0.10</min>
          				<max>30.0</max>
          				<resolution>0.01</resolution>
        			</range>
        				<noise>
          					<type>gaussian</type>
        <!--   Noise parameters based on published spec for Hokuyo laser
               achieving "+-30mm" accuracy at range < 10m.  A mean of 0.0m and
               stddev of 0.01m will put 99.7% of samples within 0.03m of the true
               reading. -->
          					<mean>0.0</mean>
          					<stddev>0.01</stddev>
        				</noise>
      			</ray>
			
   			<plugin name="gazebo_ros_range" filename="libgazebo_ros_range.so">
        			<topicName>/laser/scan/cf</topicName>
        			<frameName>cf_sensor_link</frameName>
      			</plugin>
    		</sensor>
  	</gazebo>

	
	
	<!-- central back ------------------------------------------------------------------ -->
        
	<joint name="cb_sensor" type="fixed">
                <axis xyz="0 1 0" />
                <origin xyz="-0.1 0 0.005" rpy="0 0 3.1415"/>
                <parent link="body"/>
                <child link="cb_sensor_link"/>
        </joint>
	
	<link name="cb_sensor_link">
                <collision>
                        <origin xyz="0 0 0" rpy="0 0 0"/>
                        <geometry>
                                <box size="0.1 0.1 0.1"/>
                        </geometry>
                </collision>
                
        	<inertial>
                	<mass value="1e-5" />
                	<origin xyz="0 0 0" rpy="0 0 0"/>
               		<inertia ixx="1e-6" ixy="0" ixz="0" iyy="1e-6" iyz="0" izz="1e-6" />
        	</inertial>
        </link>

        <gazebo reference="cb_sensor_link">
    		<sensor type="ray" name='cb_sensor'>
      			<pose>0 0 0 0 0 0</pose>
      			<visualize>true</visualize>
      			<update_rate>40</update_rate>
      			<ray>
        			<scan>
          				<horizontal>
            					<samples>720</samples>
            					<resolution>1</resolution>
            					<min_angle>-0.4</min_angle>
            					<max_angle>0.4</max_angle>
          				</horizontal>
        			</scan>
       				<range>
          				<min>0.10</min>
          				<max>30.0</max>
          				<resolution>0.01</resolution>
        			</range>
        				<noise>
          					<type>gaussian</type>
        <!--   Noise parameters based on published spec for Hokuyo laser
               achieving "+-30mm" accuracy at range < 10m.  A mean of 0.0m and
               stddev of 0.01m will put 99.7% of samples within 0.03m of the true
               reading. -->
          					<mean>0.0</mean>
          					<stddev>0.01</stddev>
        				</noise>
      			</ray>
			
   			<plugin name="gazebo_ros_range" filename="libgazebo_ros_range.so">
        			<topicName>/laser/scan/cb</topicName>
        			<frameName>cb_sensor_link</frameName>
      			</plugin>
    		</sensor>
  	</gazebo>

	<!-- central right ------------------------------------------------------------------ -->
        
	<joint name="cr_sensor" type="fixed">
                <axis xyz="0 1 0" />
                <origin xyz="0 -0.087 0.005" rpy="0 0 -1.570796"/>
                <parent link="body"/>
                <child link="cr_sensor_link"/>
        </joint>
	
	<link name="cr_sensor_link">
                <collision>
                        <origin xyz="0 0 0" rpy="0 0 0"/>
                        <geometry>
                                <box size="0.1 0.1 0.1"/>
                        </geometry>
                </collision>
                
        	<inertial>
                	<mass value="1e-5" />
                	<origin xyz="0 0 0" rpy="0 0 0"/>
               		<inertia ixx="1e-6" ixy="0" ixz="0" iyy="1e-6" iyz="0" izz="1e-6" />
        	</inertial>
        </link>

        <gazebo reference="cr_sensor_link">
    		<sensor type="ray" name='cr_sensor'>
      			<pose>0 0 0 0 0 0</pose>
      			<visualize>true</visualize>
      			<update_rate>40</update_rate>
      			<ray>
        			<scan>
          				<horizontal>
            					<samples>720</samples>
            					<resolution>1</resolution>
            					<min_angle>-0.4</min_angle>
            					<max_angle>0.4</max_angle>
          				</horizontal>
        			</scan>
       				<range>
          				<min>0.10</min>
          				<max>30.0</max>
          				<resolution>0.01</resolution>
        			</range>
        				<noise>
          					<type>gaussian</type>
        <!--   Noise parameters based on published spec for Hokuyo laser
               achieving "+-30mm" accuracy at range < 10m.  A mean of 0.0m and
               stddev of 0.01m will put 99.7% of samples within 0.03m of the true
               reading. --> 
          					<mean>0.0</mean>
          					<stddev>0.01</stddev>
        				</noise>
      			</ray>
			
   			<plugin name="gazebo_ros_range" filename="libgazebo_ros_range.so">
        			<topicName>/laser/scan/cr</topicName>
        			<frameName>cr_sensor_link</frameName>
      			</plugin>
    		</sensor>
  	</gazebo>

	  <!-- central left ------------------------------------------------------------------ -->

	<joint name="cl_sensor" type="fixed">
                <axis xyz="0 1 0" />
                <origin xyz="0 0.087 0.005" rpy="0 0 1.570796"/>
                <parent link="body"/>
                <child link="cl_sensor_link"/>
        </joint>
	
	<link name="cl_sensor_link">
                <collision>
                        <origin xyz="0 0 0" rpy="0 0 0"/>
                        <geometry>
                                <box size="0.1 0.1 0.1"/>
                        </geometry>
                </collision>
                
        	<inertial>
                	<mass value="1e-5" />
                	<origin xyz="0 0 0" rpy="0 0 0"/>
               		<inertia ixx="1e-6" ixy="0" ixz="0" iyy="1e-6" iyz="0" izz="1e-6" />
        	</inertial>
        </link>

        <gazebo reference="cl_sensor_link">
    		<sensor type="ray" name='cl_sensor'>
      			<pose>0 0 0 0 0 0</pose>
      			<visualize>true</visualize>
      			<update_rate>40</update_rate>
      			<ray>
        			<scan>
          				<horizontal>
            					<samples>720</samples>
            					<resolution>1</resolution>
            					<min_angle>-0.4</min_angle>
            					<max_angle>0.4</max_angle>
          				</horizontal>
        			</scan>
       				<range>
          				<min>0.10</min>
          				<max>30.0</max>
          				<resolution>0.01</resolution>
        			</range>
        				<noise>
          					<type>gaussian</type>
        <!--   Noise parameters based on published spec for Hokuyo laser
               achieving "+-30mm" accuracy at range < 10m.  A mean of 0.0m and
               stddev of 0.01m will put 99.7% of samples within 0.03m of the true
               reading. -->
          					<mean>0.0</mean>
          					<stddev>0.01</stddev>
        				</noise>
      			</ray>
			
   			<plugin name="gazebo_ros_range" filename="libgazebo_ros_range.so">
        			<topicName>/laser/scan/cl</topicName>
        			<frameName>cl_sensor_link</frameName>
      			</plugin>
    		</sensor>
  	</gazebo>


	
	<!-- front left ------------------------------------------------------------------ -->

	<joint name="fl_sensor" type="fixed">
                <axis xyz="0 1 0" />
                <origin xyz="0.1 0.087 0.005" rpy="0 0 0.785398"/>
                <parent link="body"/>
                <child link="fl_sensor_link"/>
        </joint>
	
	<link name="fl_sensor_link">
                <collision>
                        <origin xyz="0 0 0" rpy="0 0 0"/>
                        <geometry>
                                <box size="0.1 0.1 0.1"/>
                        </geometry>
                </collision>
                
        	<inertial>
                	<mass value="1e-5" />
                	<origin xyz="0 0 0" rpy="0 0 0"/>
               		<inertia ixx="1e-6" ixy="0" ixz="0" iyy="1e-6" iyz="0" izz="1e-6" />
        	</inertial>
        </link>

        <gazebo reference="fl_sensor_link">
    		<sensor type="ray" name='fl_sensor'>
      			<pose>0 0 0 0 0 0</pose>
      			<visualize>true</visualize>
      			<update_rate>40</update_rate>
      			<ray>
        			<scan>
          				<horizontal>
            					<samples>720</samples>
            					<resolution>1</resolution>
            					<min_angle>-0.4</min_angle>
            					<max_angle>0.4</max_angle>
          				</horizontal>
        			</scan>
       				<range>
          				<min>0.10</min>
          				<max>30.0</max>
          				<resolution>0.01</resolution>
        			</range>
        				<noise>
          					<type>gaussian</type>
        <!--   Noise parameters based on published spec for Hokuyo laser
               achieving "+-30mm" accuracy at range < 10m.  A mean of 0.0m and
               stddev of 0.01m will put 99.7% of samples within 0.03m of the true
               reading. -->
          					<mean>0.0</mean>
          					<stddev>0.01</stddev>
        				</noise>
      			</ray>
			
   			<plugin name="gazebo_ros_range" filename="libgazebo_ros_range.so">
        			<topicName>/laser/scan/fl</topicName>
        			<frameName>fl_sensor_link</frameName>
      			</plugin>
    		</sensor>
  	</gazebo>


	<!-- front right ------------------------------------------------------------------ -->

	<joint name="fr_sensor" type="fixed">
                <axis xyz="0 1 0" />
                <origin xyz="0.1 -0.087 0.005" rpy="0 0 -0.785398"/>
                <parent link="body"/>
                <child link="fr_sensor_link"/>
        </joint>
	
	<link name="fr_sensor_link">
                <collision>
                        <origin xyz="0 0 0" rpy="0 0 0"/>
                        <geometry>
                                <box size="0.1 0.1 0.1"/>
                        </geometry>
                </collision>
                
        	<inertial>
                	<mass value="1e-5" />
                	<origin xyz="0 0 0" rpy="0 0 0"/>
               		<inertia ixx="1e-6" ixy="0" ixz="0" iyy="1e-6" iyz="0" izz="1e-6" />
        	</inertial>
        </link>

        <gazebo reference="fr_sensor_link">
    		<sensor type="ray" name='fr_sensor'>
      			<pose>0 0 0 0 0 0</pose>
      			<visualize>true</visualize>
      			<update_rate>40</update_rate>
      			<ray>
        			<scan>
          				<horizontal>
            					<samples>720</samples>
            					<resolution>1</resolution>
            					<min_angle>-0.4</min_angle>
            					<max_angle>0.4</max_angle>
          				</horizontal>
        			</scan>
       				<range>
          				<min>0.10</min>
          				<max>30.0</max>
          				<resolution>0.01</resolution>
        			</range>
        				<noise>
          					<type>gaussian</type>
        <!--   Noise parameters based on published spec for Hokuyo laser
               achieving "+-30mm" accuracy at range < 10m.  A mean of 0.0m and
               stddev of 0.01m will put 99.7% of samples within 0.03m of the true
               reading. -->
          					<mean>0.0</mean>
          					<stddev>0.01</stddev>
        				</noise>
      			</ray>
			
   			<plugin name="gazebo_ros_range" filename="libgazebo_ros_range.so">
        			<topicName>/laser/scan/fr</topicName>
        			<frameName>fr_sensor_link</frameName>
      			</plugin>
    		</sensor>
  	</gazebo>

	<!-- back right ------------------------------------------------------------------ -->

	<joint name="br_sensor" type="fixed">
                <axis xyz="0 1 0" />
                <origin xyz="-0.1 -0.087 0.005" rpy="0 0 -2.356194"/>
                <parent link="body"/>
                <child link="br_sensor_link"/>
        </joint>
	
	<link name="br_sensor_link">
                <collision>
                        <origin xyz="0 0 0" rpy="0 0 0"/>
                        <geometry>
                                <box size="0.1 0.1 0.1"/>
                        </geometry>
                </collision>
                
        	<inertial>
                	<mass value="1e-5" />
                	<origin xyz="0 0 0" rpy="0 0 0"/>
               		<inertia ixx="1e-6" ixy="0" ixz="0" iyy="1e-6" iyz="0" izz="1e-6" />
        	</inertial>
        </link>

        <gazebo reference="br_sensor_link">
    		<sensor type="ray" name='br_sensor'>
      			<pose>0 0 0 0 0 0</pose>
      			<visualize>true</visualize>
      			<update_rate>40</update_rate>
      			<ray>
        			<scan>
          				<horizontal>
            					<samples>720</samples>
            					<resolution>1</resolution>
            					<min_angle>-0.4</min_angle>
            					<max_angle>0.4</max_angle>
          				</horizontal>
        			</scan>
       				<range>
          				<min>0.10</min>
          				<max>30.0</max>
          				<resolution>0.01</resolution>
        			</range>
        				<noise>
          					<type>gaussian</type>
        <!--   Noise parameters based on published spec for Hokuyo laser
               achieving "+-30mm" accuracy at range < 10m.  A mean of 0.0m and
               stddev of 0.01m will put 99.7% of samples within 0.03m of the true
               reading. -->
          					<mean>0.0</mean>
          					<stddev>0.01</stddev>
        				</noise>
      			</ray>
			
   			<plugin name="gazebo_ros_range" filename="libgazebo_ros_range.so">
        			<topicName>/laser/scan/br</topicName>
        			<frameName>br_sensor_link</frameName>
      			</plugin>
    		</sensor>
  	</gazebo>


<!-- back left ------------------------------------------------------------------ -->

	<joint name="bl_sensor" type="fixed">
                <axis xyz="0 1 0" />
                <origin xyz="-0.1 0.087 0.005" rpy="0 0 2.356194"/>
                <parent link="body"/>
                <child link="bl_sensor_link"/>
        </joint>
	
	<link name="bl_sensor_link">
                <collision>
                        <origin xyz="0 0 0" rpy="0 0 0"/>
                        <geometry>
                                <box size="0.1 0.1 0.1"/>
                        </geometry>
                </collision>
                
        	<inertial>
                	<mass value="1e-5" />
                	<origin xyz="0 0 0" rpy="0 0 0"/>
               		<inertia ixx="1e-6" ixy="0" ixz="0" iyy="1e-6" iyz="0" izz="1e-6" />
        	</inertial>
        </link>

        <gazebo reference="bl_sensor_link">
    		<sensor type="ray" name='bl_sensor'>
      			<pose>0 0 0 0 0 0</pose>
      			<visualize>true</visualize>
      			<update_rate>40</update_rate>
      			<ray>
        			<scan>
          				<horizontal>
            					<samples>720</samples>
            					<resolution>1</resolution>
            					<min_angle>-0.4</min_angle>
            					<max_angle>0.4</max_angle>
          				</horizontal>
        			</scan>
       				<range>
          				<min>0.10</min>
          				<max>30.0</max>
          				<resolution>0.01</resolution>
        			</range>
        				<noise>
          					<type>gaussian</type>
        <!--   Noise parameters based on published spec for Hokuyo laser
               achieving "+-30mm" accuracy at range < 10m.  A mean of 0.0m and
               stddev of 0.01m will put 99.7% of samples within 0.03m of the true
               reading. -->
          					<mean>0.0</mean>
          					<stddev>0.01</stddev>
        				</noise>
      			</ray>
			
   			<plugin name="gazebo_ros_range" filename="libgazebo_ros_range.so">
        			<topicName>/laser/scan/bl</topicName>
        			<frameName>bl_sensor_link</frameName>
      			</plugin>
    		</sensor>
  	</gazebo>

	<gazebo>
		<plugin name="skid_steer_drive_controller" filename="libgazebo_ros_skid_steer_drive.so">
			<updateRate>100.0</updateRate>
    			<robotNamespace>/</robotNamespace>
    			<leftFrontJoint>base_to_lf_wheel</leftFrontJoint>
    			<rightFrontJoint>base_to_rf_wheel</rightFrontJoint>
    			<leftRearJoint>base_to_lb_wheel</leftRearJoint>
    			<rightRearJoint>base_to_rb_wheel</rightRearJoint>
   		 	<wheelSeparation>0.4</wheelSeparation>
    			<wheelDiameter>0.064</wheelDiameter>
 			<robotBaseFrame>base_link</robotBaseFrame>
    			<torque>20</torque>
    			<topicName>cmd_vel</topicName>
    			<broadcastTF>false</broadcastTF>
  		</plugin>
	</gazebo>
</robot>