<robot
  name="robot_description">
  <link
    name="base_link">
    <inertial>
      <origin
        xyz="0.078275 -0.034869 -0.0048269"
        rpy="0 0 0" />
      <mass
        value="0.65449" />
      <inertia
        ixx="7.9164E-06"
        ixy="-1.7628E-06"
        ixz="-3.9464E-06"
        iyy="9.5004E-06"
        iyz="-2.9238E-06"
        izz="4.1674E-06" />
    </inertial>
    <visual>
      <origin
        xyz="0 0 0"
        rpy="0 0 0" />
      <geometry>
        <mesh
          filename="package://robot_description/meshes/base_link.STL" />
      </geometry>
      <material
        name="">
        <color
          rgba="0.74902 0.74902 0.74902 1" />
      </material>
    </visual>
    <collision>
      <origin
        xyz="0 0 0"
        rpy="0 0 0" />
      <geometry>
        <mesh
          filename="package://robot_description/meshes/base_link.STL" />
      </geometry>
    </collision>
  </link>
  <link
    name="sworzen1">
    <inertial>
      <origin
        xyz="-0.00072575 0.00079945 0.0011536"
        rpy="0 0 0" />
      <mass
        value="0.66332" />
      <inertia
        ixx="7.6167E-05"
        ixy="7.7219E-07"
        ixz="-3.8815E-05"
        iyy="8.8837E-05"
        iyz="6.1173E-07"
        izz="3.3447E-05" />
    </inertial>
    <visual>
      <origin
        xyz="0 0 0"
        rpy="0 0 0" />
      <geometry>
        <mesh
          filename="package://robot_description/meshes/sworzen1.STL" />
      </geometry>
      <material
        name="">
        <color
          rgba="0.74902 0.74902 0.74902 1" />
      </material>
    </visual>
    <collision>
      <origin
        xyz="0 0 0"
        rpy="0 0 0" />
      <geometry>
        <mesh
          filename="package://robot_description/meshes/sworzen1.STL" />
      </geometry>
    </collision>
  </link>
  <joint
    name="sworzen1_joint"
    type="revolute">
    <origin
      xyz="0.078656 0.0046714 -0.033295"
      rpy="-1.0935 -1.209 1.6195" />
    <parent
      link="base_link" />
    <child
      link="sworzen1" />
    <axis
      xyz="0 0 0" />
    <limit
      lower="-1.57"
      upper="1.57"
      effort="0"
      velocity="0" />
  </joint>
  <link
    name="ramie1">
    <inertial>
      <origin
        xyz="0.039116 -0.016671 0.025"
        rpy="0 0 0" />
      <mass
        value="0.083887" />
      <inertia
        ixx="7.3546E-06"
        ixy="6.4402E-06"
        ixz="-2.9996E-18"
        iyy="1.9721E-05"
        iyz="1.2714E-18"
        izz="1.7856E-05" />
    </inertial>
    <visual>
      <origin
        xyz="0 0 0"
        rpy="0 0 0" />
      <geometry>
        <mesh
          filename="package://robot_description/meshes/ramie1.STL" />
      </geometry>
      <material
        name="">
        <color
          rgba="1 0.70196 0.18039 1" />
      </material>
    </visual>
    <collision>
      <origin
        xyz="0 0 0"
        rpy="0 0 0" />
      <geometry>
        <mesh
          filename="package://robot_description/meshes/ramie1.STL" />
      </geometry>
    </collision>
  </link>
  <joint
    name="ramie1_joint"
    type="revolute">
    <origin
      xyz="0.028349 0 0.099103"
      rpy="-2.3896 0.81672 -2.2328" />
    <parent
      link="sworzen1" />
    <child
      link="ramie1" />
    <axis
      xyz="0 0 0" />
    <limit
      lower="-1.57"
      upper="1.57"
      effort="0"
      velocity="0" />
  </joint>
  <link
    name="ramie1_sworzen">
    <inertial>
      <origin
        xyz="0.015 0.050989 -1.266E-14"
        rpy="0 0 0" />
      <mass
        value="0.080353" />
      <inertia
        ixx="1.8244E-05"
        ixy="-5.1486E-16"
        ixz="-7.0107E-17"
        iyy="4.6099E-06"
        iyz="-1.4312E-16"
        izz="1.3634E-05" />
    </inertial>
    <visual>
      <origin
        xyz="0 0 0"
        rpy="0 0 0" />
      <geometry>
        <mesh
          filename="package://robot_description/meshes/ramie1_sworzen.STL" />
      </geometry>
      <material
        name="">
        <color
          rgba="0.74902 0.74902 0.74902 1" />
      </material>
    </visual>
    <collision>
      <origin
        xyz="0 0 0"
        rpy="0 0 0" />
      <geometry>
        <mesh
          filename="package://robot_description/meshes/ramie1_sworzen.STL" />
      </geometry>
    </collision>
  </link>
  <joint
    name="ramie1_sworzen_joint"
    type="revolute">
    <origin
      xyz="0.005881 0.013799 0.025"
      rpy="-3.3307E-16 -9.992E-16 -1.9737" />
    <parent
      link="ramie1" />
    <child
      link="ramie1_sworzen" />
    <axis
      xyz="0 0 0" />
    <limit
      lower="-1.57"
      upper="1.57"
      effort="0"
      velocity="0" />
  </joint>
  <link
    name="kolo1">
    <inertial>
      <origin
        xyz="0.0075 -1.1102E-16 1.3878E-16"
        rpy="0 0 0" />
      <mass
        value="0.040766" />
      <inertia
        ixx="9.7492E-33"
        ixy="-3.8705E-32"
        ixz="4.7429E-32"
        iyy="3.903E-31"
        iyz="4.7755E-33"
        izz="3.8835E-31" />
    </inertial>
    <visual>
      <origin
        xyz="0 0 0"
        rpy="0 0 0" />
      <geometry>
        <mesh
          filename="package://robot_description/meshes/kolo1.STL" />
      </geometry>
      <material
        name="">
        <color
          rgba="0.019608 0.019608 0.019608 1" />
      </material>
    </visual>
    <collision>
      <origin
        xyz="0 0 0"
        rpy="0 0 0" />
      <geometry>
        <mesh
          filename="package://robot_description/meshes/kolo1.STL" />
      </geometry>
    </collision>
  </link>
  <joint
    name="kolo1_joint"
    type="continuous">
    <origin
      xyz="0.015 0.1 -0.0075"
      rpy="1.2654 -1.5708 0" />
    <parent
      link="ramie1_sworzen" />
    <child
      link="kolo1" />
    <axis
      xyz="0 0 0" />
  </joint>
  <link
    name="sworzen2">
    <inertial>
      <origin
        xyz="-0.00272380950321219 0.000799447417495533 2.44942954807925E-14"
        rpy="0 0 0" />
      <mass
        value="0.663324587071708" />
      <inertia
        ixx="1.0781283135998E-05"
        ixy="-2.87368565427112E-07"
        ixz="2.62257705854166E-16"
        iyy="8.51479121796059E-05"
        iyz="-9.3770274206019E-16"
        izz="9.51428553386611E-05" />
    </inertial>
    <visual>
      <origin
        xyz="0 0 0"
        rpy="0 0 0" />
      <geometry>
        <mesh
          filename="package://robot_description/meshes/sworzen2.STL" />
      </geometry>
      <material
        name="">
        <color
          rgba="0.749019607843137 0.749019607843137 0.749019607843137 1" />
      </material>
    </visual>
    <collision>
      <origin
        xyz="0 0 0"
        rpy="0 0 0" />
      <geometry>
        <mesh
          filename="package://robot_description/meshes/sworzen2.STL" />
      </geometry>
    </collision>
  </link>
  <joint
    name="sworzen2_joint"
    type="revolute">
    <origin
      xyz="0.078656 0.0046714 -0.033295"
      rpy="-1.0935 -1.209 1.6195" />
    <parent
      link="base_link" />
    <child
      link="sworzen2" />
    <axis
      xyz="0 0 0" />
    <limit
      lower="-1.57"
      upper="1.57"
      effort="0"
      velocity="0" />
  </joint>
  <link
    name="ramie2">
    <inertial>
      <origin
        xyz="0.0421192530367286 -0.00582961002139445 0.025000000000007"
        rpy="0 0 0" />
      <mass
        value="0.0838871669414958" />
      <inertia
        ixx="4.94549577563115E-06"
        ixy="2.42492929143536E-06"
        ixz="-2.93274570074961E-18"
        iyy="2.21301154817376E-05"
        iyz="4.03611199366674E-19"
        izz="1.78558752997074E-05" />
    </inertial>
    <visual>
      <origin
        xyz="0 0 0"
        rpy="0 0 0" />
      <geometry>
        <mesh
          filename="package://robot_description/meshes/ramie2.STL" />
      </geometry>
      <material
        name="">
        <color
          rgba="1 0.701960784313725 0.180392156862745 1" />
      </material>
    </visual>
    <collision>
      <origin
        xyz="0 0 0"
        rpy="0 0 0" />
      <geometry>
        <mesh
          filename="package://robot_description/meshes/ramie2.STL" />
      </geometry>
    </collision>
  </link>
  <joint
    name="ramie2_joint"
    type="revolute">
    <origin
      xyz="-0.1 0 -0.025"
      rpy="3.8858E-16 2.498E-16 -0.89513" />
    <parent
      link="sworzen2" />
    <child
      link="ramie2" />
    <axis
      xyz="0 0 0" />
    <limit
      lower="-1.57"
      upper="1.57"
      effort="0"
      velocity="0" />
  </joint>
  <link
    name="ramie2_sworzen">
    <inertial>
      <origin
        xyz="0.0149999999998696 0.0509887247958938 7.81041897823798E-14"
        rpy="0 0 0" />
      <mass
        value="0.0803528752062073" />
      <inertia
        ixx="1.82440178904883E-05"
        ixy="-5.25535980530655E-16"
        ixz="1.69313204068425E-15"
        iyy="4.60986798277215E-06"
        iyz="2.91141635234656E-16"
        izz="1.36341499136656E-05" />
    </inertial>
    <visual>
      <origin
        xyz="0 0 0"
        rpy="0 0 0" />
      <geometry>
        <mesh
          filename="package://robot_description/meshes/ramie2_sworzen.STL" />
      </geometry>
      <material
        name="">
        <color
          rgba="0.749019607843137 0.749019607843137 0.749019607843137 1" />
      </material>
    </visual>
    <collision>
      <origin
        xyz="0 0 0"
        rpy="0 0 0" />
      <geometry>
        <mesh
          filename="package://robot_description/meshes/ramie2_sworzen.STL" />
      </geometry>
    </collision>
  </link>
  <joint
    name="ramie2_sworzen_joint"
    type="revolute">
    <origin
      xyz="0.0020565 0.014858 0.025"
      rpy="4.4409E-16 -1.0547E-15 -1.7083" />
    <parent
      link="ramie2" />
    <child
      link="ramie2_sworzen" />
    <axis
      xyz="0 0 0" />
    <limit
      lower="-1.57"
      upper="1.57"
      effort="0"
      velocity="0" />
  </joint>
  <link
    name="kolo2">
    <inertial>
      <origin
        xyz="3.95516952522712E-15 3.99680288865056E-15 0.0150000000000207"
        rpy="0 0 0" />
      <mass
        value="0.0407655519524368" />
      <inertia
        ixx="2.69854716272748E-30"
        ixy="-9.61630206689141E-32"
        ixz="-4.96191017407152E-31"
        iyy="2.69552169443467E-30"
        iyz="-5.04057980394581E-31"
        izz="1.92354047984905E-31" />
    </inertial>
    <visual>
      <origin
        xyz="0 0 0"
        rpy="0 0 0" />
      <geometry>
        <mesh
          filename="package://robot_description/meshes/kolo2.STL" />
      </geometry>
      <material
        name="">
        <color
          rgba="1 0.701960784313725 0.180392156862745 1" />
      </material>
    </visual>
    <collision>
      <origin
        xyz="0 0 0"
        rpy="0 0 0" />
      <geometry>
        <mesh
          filename="package://robot_description/meshes/kolo2.STL" />
      </geometry>
    </collision>
  </link>
  <joint
    name="kolo2_joint"
    type="continuous">
    <origin
      xyz="0.015 0.1 -0.015"
      rpy="-6.4948E-15 1.3323E-15 -2.0595" />
    <parent
      link="ramie2_sworzen" />
    <child
      link="kolo2" />
    <axis
      xyz="0 0 0" />
  </joint>
  <link
    name="sworzen3">
    <inertial>
      <origin
        xyz="-0.000725753910875128 0.00079944741749554 -0.00115357793406713"
        rpy="0 0 0" />
      <mass
        value="0.663324587071708" />
      <inertia
        ixx="7.61665392518774E-05"
        ixy="7.72186584742255E-07"
        ixz="3.88151747695803E-05"
        iyy="8.88371095580954E-05"
        iyz="-6.11734452109273E-07"
        izz="3.34467966012712E-05" />
    </inertial>
    <visual>
      <origin
        xyz="0 0 0"
        rpy="0 0 0" />
      <geometry>
        <mesh
          filename="package://robot_description/meshes/sworzen3.STL" />
      </geometry>
      <material
        name="">
        <color
          rgba="0.749019607843137 0.749019607843137 0.749019607843137 1" />
      </material>
    </visual>
    <collision>
      <origin
        xyz="0 0 0"
        rpy="0 0 0" />
      <geometry>
        <mesh
          filename="package://robot_description/meshes/sworzen3.STL" />
      </geometry>
    </collision>
  </link>
  <joint
    name="sworzen3_joint"
    type="revolute">
    <origin
      xyz="0.078656 0.0046714 -0.033295"
      rpy="-1.0935 -1.209 1.6195" />
    <parent
      link="base_link" />
    <child
      link="sworzen3" />
    <axis
      xyz="0 0 0" />
    <limit
      lower="-1.57"
      upper="1.57"
      effort="0"
      velocity="0" />
  </joint>
  <link
    name="ramie3">
    <inertial>
      <origin
        xyz="0.036910735631314 0.021109557658291 0.0250000000000001"
        rpy="0 0 0" />
      <mass
        value="0.0838871669414958" />
      <inertia
        ixx="9.01072421641597E-06"
        ixy="-7.69503765851921E-06"
        ixz="1.64112633530521E-21"
        iyy="1.80648870409523E-05"
        iyz="-1.95082275664506E-20"
        izz="1.78558752997069E-05" />
    </inertial>
    <visual>
      <origin
        xyz="0 0 0"
        rpy="0 0 0" />
      <geometry>
        <mesh
          filename="package://robot_description/meshes/ramie3.STL" />
      </geometry>
      <material
        name="">
        <color
          rgba="1 0.701960784313725 0.180392156862745 1" />
      </material>
    </visual>
    <collision>
      <origin
        xyz="0 0 0"
        rpy="0 0 0" />
      <geometry>
        <mesh
          filename="package://robot_description/meshes/ramie3.STL" />
      </geometry>
    </collision>
  </link>
  <joint
    name="ramie3_joint"
    type="revolute">
    <origin
      xyz="0.028349 0 -0.099103"
      rpy="-0.41636 -0.99237 -2.6557" />
    <parent
      link="sworzen3" />
    <child
      link="ramie3" />
    <axis
      xyz="0 0 0" />
    <limit
      lower="-1.57"
      upper="1.57"
      effort="0"
      velocity="0" />
  </joint>
  <link
    name="ramie3_sworzen">
    <inertial>
      <origin
        xyz="0.0149999999998713 0.0509887247959366 -6.72517597166689E-14"
        rpy="0 0 0" />
      <mass
        value="0.0803528752062073" />
      <inertia
        ixx="1.82440178901915E-05"
        ixy="4.49395024231664E-16"
        ixz="-1.42210268662145E-15"
        iyy="4.60986798242077E-06"
        iyz="2.31757796428992E-16"
        izz="1.36341499135455E-05" />
    </inertial>
    <visual>
      <origin
        xyz="0 0 0"
        rpy="0 0 0" />
      <geometry>
        <mesh
          filename="package://robot_description/meshes/ramie3_sworzen.STL" />
      </geometry>
      <material
        name="">
        <color
          rgba="0.749019607843137 0.749019607843137 0.749019607843137 1" />
      </material>
    </visual>
    <collision>
      <origin
        xyz="0 0 0"
        rpy="0 0 0" />
      <geometry>
        <mesh
          filename="package://robot_description/meshes/ramie3_sworzen.STL" />
      </geometry>
    </collision>
  </link>
  <joint
    name="ramie3_sworzen_joint"
    type="revolute">
    <origin
      xyz="0.0074468 -0.013021 0.025"
      rpy="3.1416 1.1328E-15 2.0903" />
    <parent
      link="ramie3" />
    <child
      link="ramie3_sworzen" />
    <axis
      xyz="0 0 0" />
    <limit
      lower="-1.57"
      upper="1.57"
      effort="0"
      velocity="0" />
  </joint>
  <link
    name="kolo3">
    <inertial>
      <origin
        xyz="1.2490009027033E-16 -5.55111512312578E-17 0.015000000000006"
        rpy="0 0 0" />
      <mass
        value="0.0407655519524369" />
      <inertia
        ixx="2.18424991966655E-31"
        ixy="5.43344684551267E-35"
        ixz="-5.68002756726361E-33"
        iyy="2.18563956931501E-31"
        iyz="2.34986981921875E-33"
        izz="1.94384518096186E-34" />
    </inertial>
    <visual>
      <origin
        xyz="0 0 0"
        rpy="0 0 0" />
      <geometry>
        <mesh
          filename="package://robot_description/meshes/kolo3.STL" />
      </geometry>
      <material
        name="">
        <color
          rgba="1 0.701960784313725 0.180392156862745 1" />
      </material>
    </visual>
    <collision>
      <origin
        xyz="0 0 0"
        rpy="0 0 0" />
      <geometry>
        <mesh
          filename="package://robot_description/meshes/kolo3.STL" />
      </geometry>
    </collision>
  </link>
  <joint
    name="kolo3_joint"
    type="continuous">
    <origin
      xyz="0.015 0.1 0.015"
      rpy="-3.1416 3.1572E-16 0.26592" />
    <parent
      link="ramie3_sworzen" />
    <child
      link="kolo3" />
    <axis
      xyz="0 0 0" />
  </joint>
  <link
    name="ramie_gora">
    <inertial>
      <origin
        xyz="-0.00139922773445356 0.00104478083575374 2.46191955710628E-14"
        rpy="0 0 0" />
      <mass
        value="0.65979029533642" />
      <inertia
        ixx="1.52563131405609E-05"
        ixy="1.92510488351944E-07"
        ixz="2.85446503334673E-16"
        iyy="4.20152907733352E-07"
        iyz="-9.3342624476307E-16"
        izz="1.48901260713515E-05" />
    </inertial>
    <visual>
      <origin
        xyz="0 0 0"
        rpy="0 0 0" />
      <geometry>
        <mesh
          filename="package://robot_description/meshes/ramie_gora.STL" />
      </geometry>
      <material
        name="">
        <color
          rgba="0.749019607843137 0.749019607843137 0.749019607843137 1" />
      </material>
    </visual>
    <collision>
      <origin
        xyz="0 0 0"
        rpy="0 0 0" />
      <geometry>
        <mesh
          filename="package://robot_description/meshes/ramie_gora.STL" />
      </geometry>
    </collision>
  </link>
  <joint
    name="ramie_gora_joint"
    type="fixed">
    <origin
      xyz="0.078656 0.0046714 -0.033295"
      rpy="-1.0935 -1.209 1.6195" />
    <parent
      link="base_link" />
    <child
      link="ramie_gora" />
    <axis
      xyz="0 0 0" />
  </joint>
  <link
    name="ramie_ruch1">
    <inertial>
      <origin
        xyz="-0.0249903327813365 -0.0362608136338515 0.0150000000000007"
        rpy="0 0 0" />
      <mass
        value="0.0824025158054101" />
      <inertia
        ixx="7.44987118581313E-06"
        ixy="-5.13432384588075E-06"
        ixz="-5.61159327555974E-19"
        iyy="3.53848820970215E-06"
        iyz="-5.1086674631275E-19"
        izz="1.09883593954399E-05" />
    </inertial>
    <visual>
      <origin
        xyz="0 0 0"
        rpy="0 0 0" />
      <geometry>
        <mesh
          filename="package://robot_description/meshes/ramie_ruch1.STL" />
      </geometry>
      <material
        name="">
        <color
          rgba="1 0.701960784313725 0.180392156862745 1" />
      </material>
    </visual>
    <collision>
      <origin
        xyz="0 0 0"
        rpy="0 0 0" />
      <geometry>
        <mesh
          filename="package://robot_description/meshes/ramie_ruch1.STL" />
      </geometry>
    </collision>
  </link>
  <joint
    name="ramie_ruch1_joint"
    type="revolute">
    <origin
      xyz="0 0.03 -0.015"
      rpy="3.0531E-16 -9.4369E-16 -2.341" />
    <parent
      link="ramie_gora" />
    <child
      link="ramie_ruch1" />
    <axis
      xyz="0 0 0" />
    <limit
      lower="-1.57"
      upper="1.57"
      effort="0"
      velocity="0" />
  </joint>
  <link
    name="sworzen_ramie_ruch">
    <inertial>
      <origin
        xyz="0.0483232563870525 -0.0108797811524379 0.0156417163692359"
        rpy="0 0 0" />
      <mass
        value="0.0824025158054101" />
      <inertia
        ixx="6.73011138679717E-07"
        ixy="2.97885954380119E-06"
        ixz="-1.75700494717498E-07"
        iyy="1.32331318644119E-05"
        iyz="3.95582391133261E-08"
        izz="1.39014765177605E-05" />
    </inertial>
    <visual>
      <origin
        xyz="0 0 0"
        rpy="0 0 0" />
      <geometry>
        <mesh
          filename="package://robot_description/meshes/sworzen_ramie_ruch.STL" />
      </geometry>
      <material
        name="">
        <color
          rgba="1 0.701960784313725 0.180392156862745 1" />
      </material>
    </visual>
    <collision>
      <origin
        xyz="0 0 0"
        rpy="0 0 0" />
      <geometry>
        <mesh
          filename="package://robot_description/meshes/sworzen_ramie_ruch.STL" />
      </geometry>
    </collision>
  </link>
  <joint
    name="sworzen_ramie_ruch_joint"
    type="revolute">
    <origin
      xyz="-0.070166 -0.072813 0.015"
      rpy="1.5708 -0.22145 0.95279" />
    <parent
      link="ramie_ruch1" />
    <child
      link="sworzen_ramie_ruch" />
    <axis
      xyz="0 0 0" />
    <limit
      lower="-1.57"
      upper="1.57"
      effort="0"
      velocity="0" />
  </joint>
  <link
    name="ramie_ruch2">
    <inertial>
      <origin
        xyz="-0.046866107452409 -0.00291694979257964 0.0150000000000038"
        rpy="0 0 0" />
      <mass
        value="0.0871028752062767" />
      <inertia
        ixx="4.64936202969211E-06"
        ixy="-7.71708079081837E-07"
        ixz="5.05339856331916E-18"
        iyy="1.70002257134525E-05"
        iyz="-1.41115689012566E-18"
        izz="1.24469260129605E-05" />
    </inertial>
    <visual>
      <origin
        xyz="0 0 0"
        rpy="0 0 0" />
      <geometry>
        <mesh
          filename="package://robot_description/meshes/ramie_ruch2.STL" />
      </geometry>
      <material
        name="">
        <color
          rgba="1 0.701960784313725 0.180392156862745 1" />
      </material>
    </visual>
    <collision>
      <origin
        xyz="0 0 0"
        rpy="0 0 0" />
      <geometry>
        <mesh
          filename="package://robot_description/meshes/ramie_ruch2.STL" />
      </geometry>
    </collision>
  </link>
  <joint
    name="ramie_ruch2_joint"
    type="revolute">
    <origin
      xyz="0 0 0"
      rpy="-5.5511E-17 0 -5.5511E-17" />
    <parent
      link="sworzen_ramie_ruch" />
    <child
      link="ramie_ruch2" />
    <axis
      xyz="0 0 0" />
    <limit
      lower="-1.57"
      upper="1.57"
      effort="0"
      velocity="0" />
  </joint>
  <link
    name="sworzen_ramie_ruch2">
    <inertial>
      <origin
        xyz="0.0150000000000238 0.0530432047106913 -1.14491749414469E-15"
        rpy="0 0 0" />
      <mass
        value="0.0871028752062767" />
      <inertia
        ixx="1.70482568781018E-05"
        ixy="7.00898588029252E-18"
        ixz="-1.71778281703172E-18"
        iyy="4.60133086509205E-06"
        iyz="-3.26245327546834E-18"
        izz="1.24469260130097E-05" />
    </inertial>
    <visual>
      <origin
        xyz="0 0 0"
        rpy="0 0 0" />
      <geometry>
        <mesh
          filename="package://robot_description/meshes/sworzen_ramie_ruch2.STL" />
      </geometry>
      <material
        name="">
        <color
          rgba="0.749019607843137 0.749019607843137 0.749019607843137 1" />
      </material>
    </visual>
    <collision>
      <origin
        xyz="0 0 0"
        rpy="0 0 0" />
      <geometry>
        <mesh
          filename="package://robot_description/meshes/sworzen_ramie_ruch2.STL" />
      </geometry>
    </collision>
  </link>
  <joint
    name="sworzen_ramie_ruch2_joint"
    type="revolute">
    <origin
      xyz="0.0009318 -0.014971 0.015"
      rpy="3.7192E-15 3.4694E-16 1.633" />
    <parent
      link="ramie_ruch2" />
    <child
      link="sworzen_ramie_ruch2" />
    <axis
      xyz="0 0 0" />
    <limit
      lower="-1.57"
      upper="1.57"
      effort="0"
      velocity="0" />
  </joint>
  <link
    name="base_up">
    <inertial>
      <origin
        xyz="-0.00548186963420297 -0.0300670324386722 0.0136007722655658"
        rpy="0 0 0" />
      <mass
        value="0.659790295336421" />
      <inertia
        ixx="1.49194628856763E-05"
        ixy="-2.64353747783547E-06"
        ixz="-1.14360431468133E-07"
        iyy="9.0212690323311E-07"
        iyz="-6.27245636862381E-07"
        izz="1.57676239492155E-05" />
    </inertial>
    <visual>
      <origin
        xyz="0 0 0"
        rpy="0 0 0" />
      <geometry>
        <mesh
          filename="package://robot_description/meshes/base_up.STL" />
      </geometry>
      <material
        name="">
        <color
          rgba="1 0.701960784313725 0.180392156862745 1" />
      </material>
    </visual>
    <collision>
      <origin
        xyz="0 0 0"
        rpy="0 0 0" />
      <geometry>
        <mesh
          filename="package://robot_description/meshes/base_up.STL" />
      </geometry>
    </collision>
  </link>
  <joint
    name="base_up_joint"
    type="revolute">
    <origin
      xyz="0.015 0.1 -0.015"
      rpy="-2.2204E-16 -9.7838E-16 -2.9613" />
    <parent
      link="sworzen_ramie_ruch2" />
    <child
      link="base_up" />
    <axis
      xyz="0 0 0" />
    <limit
      lower="-1.57"
      upper="1.57"
      effort="0"
      velocity="0" />
  </joint>
  <link
    name="sworzen5">
    <inertial>
      <origin
        xyz="-0.000725753910907526 0.000799447417343724 0.00115357793405303"
        rpy="0 0 0" />
      <mass
        value="0.66332458707171" />
      <inertia
        ixx="7.61665392990585E-05"
        ixy="7.72186574160441E-07"
        ixz="-3.88151747709922E-05"
        iyy="8.88371095594185E-05"
        iyz="6.11734441355368E-07"
        izz="3.34467966517728E-05" />
    </inertial>
    <visual>
      <origin
        xyz="0 0 0"
        rpy="0 0 0" />
      <geometry>
        <mesh
          filename="package://robot_description/meshes/sworzen5.STL" />
      </geometry>
      <material
        name="">
        <color
          rgba="0.749019607843137 0.749019607843137 0.749019607843137 1" />
      </material>
    </visual>
    <collision>
      <origin
        xyz="0 0 0"
        rpy="0 0 0" />
      <geometry>
        <mesh
          filename="package://robot_description/meshes/sworzen5.STL" />
      </geometry>
    </collision>
  </link>
  <joint
    name="sworzen5_joint"
    type="revolute">
    <origin
      xyz="-0.0053809 -0.029513 0.015"
      rpy="0.18034 -1.5708 0" />
    <parent
      link="base_up" />
    <child
      link="sworzen5" />
    <axis
      xyz="0 0 0" />
    <limit
      lower="-1.57"
      upper="1.57"
      effort="0"
      velocity="0" />
  </joint>
  <link
    name="ramie5">
    <inertial>
      <origin
        xyz="0.0423384048700489 0.00393386609244251 0.0250000000000008"
        rpy="0 0 0" />
      <mass
        value="0.0838871669414958" />
      <inertia
        ixx="4.76270130362926E-06"
        ixy="-1.64487530340014E-06"
        ixz="-3.63059497016874E-19"
        iyy="2.23129099537389E-05"
        iyz="-3.47283508374263E-20"
        izz="1.78558752997068E-05" />
    </inertial>
    <visual>
      <origin
        xyz="0 0 0"
        rpy="0 0 0" />
      <geometry>
        <mesh
          filename="package://robot_description/meshes/ramie5.STL" />
      </geometry>
      <material
        name="">
        <color
          rgba="1 0.701960784313725 0.180392156862745 1" />
      </material>
    </visual>
    <collision>
      <origin
        xyz="0 0 0"
        rpy="0 0 0" />
      <geometry>
        <mesh
          filename="package://robot_description/meshes/ramie5.STL" />
      </geometry>
    </collision>
  </link>
  <joint
    name="ramie5_joint"
    type="revolute">
    <origin
      xyz="0.028349 0 0.099103"
      rpy="2.2611 0.66778 2.0435" />
    <parent
      link="sworzen5" />
    <child
      link="ramie5" />
    <axis
      xyz="0 0 0" />
    <limit
      lower="-1.57"
      upper="1.57"
      effort="0"
      velocity="0" />
  </joint>
  <link
    name="sworzen_ramie5">
    <inertial>
      <origin
        xyz="0.040277 -0.027926 0.015"
        rpy="0 0 0" />
      <mass
        value="0.080353" />
      <inertia
        ixx="9.0361E-06"
        ixy="6.3841E-06"
        ixz="2.3251E-19"
        iyy="1.3818E-05"
        iyz="-1.3711E-19"
        izz="1.3634E-05" />
    </inertial>
    <visual>
      <origin
        xyz="0 0 0"
        rpy="0 0 0" />
      <geometry>
        <mesh
          filename="package://robot_description/meshes/sworzen_ramie5.STL" />
      </geometry>
      <material
        name="">
        <color
          rgba="1 0.70196 0.18039 1" />
      </material>
    </visual>
    <collision>
      <origin
        xyz="0 0 0"
        rpy="0 0 0" />
      <geometry>
        <mesh
          filename="package://robot_description/meshes/sworzen_ramie5.STL" />
      </geometry>
    </collision>
  </link>
  <joint
    name="sworzen_ramie5_joint"
    type="revolute">
    <origin
      xyz="0.099571 0.0092516 0.01"
      rpy="-1.1137E-15 -6.1062E-15 -2.4427" />
    <parent
      link="ramie5" />
    <child
      link="sworzen_ramie5" />
    <axis
      xyz="0 0 0" />
    <limit
      lower="-1.57"
      upper="1.57"
      effort="0"
      velocity="0" />
  </joint>
  <link
    name="kolo5">
    <inertial>
      <origin
        xyz="0 -3.8858E-16 0.015"
        rpy="0 0 0" />
      <mass
        value="0.040766" />
      <inertia
        ixx="7.4613E-32"
        ixy="-4.6515E-35"
        ixz="2.9809E-34"
        iyy="7.3562E-32"
        iyz="9.0903E-33"
        izz="1.2003E-33" />
    </inertial>
    <visual>
      <origin
        xyz="0 0 0"
        rpy="0 0 0" />
      <geometry>
        <mesh
          filename="package://robot_description/meshes/kolo5.STL" />
      </geometry>
      <material
        name="">
        <color
          rgba="1 0.70196 0.18039 1" />
      </material>
    </visual>
    <collision>
      <origin
        xyz="0 0 0"
        rpy="0 0 0" />
      <geometry>
        <mesh
          filename="package://robot_description/meshes/kolo5.STL" />
      </geometry>
    </collision>
  </link>
  <joint
    name="kolo5_joint"
    type="continuous">
    <origin
      xyz="0 0 0"
      rpy="-3.4694E-17 0 -2.7756E-17" />
    <parent
      link="sworzen_ramie5" />
    <child
      link="kolo5" />
    <axis
      xyz="0 0 0" />
  </joint>
  <link
    name="sworzen6">
    <inertial>
      <origin
        xyz="-0.000725753910907401 0.000799447417343668 -0.00115357793413019"
        rpy="0 0 0" />
      <mass
        value="0.66332458707171" />
      <inertia
        ixx="7.61665392989381E-05"
        ixy="7.72186574162983E-07"
        ixz="3.88151747676223E-05"
        iyy="8.88371095593056E-05"
        iyz="-6.11734460754431E-07"
        izz="3.34467966517806E-05" />
    </inertial>
    <visual>
      <origin
        xyz="0 0 0"
        rpy="0 0 0" />
      <geometry>
        <mesh
          filename="package://robot_description/meshes/sworzen6.STL" />
      </geometry>
      <material
        name="">
        <color
          rgba="0.749019607843137 0.749019607843137 0.749019607843137 1" />
      </material>
    </visual>
    <collision>
      <origin
        xyz="0 0 0"
        rpy="0 0 0" />
      <geometry>
        <mesh
          filename="package://robot_description/meshes/sworzen6.STL" />
      </geometry>
    </collision>
  </link>
  <joint
    name="sworzen6_joint"
    type="revolute">
    <origin
      xyz="-0.0053809 -0.029513 0.015"
      rpy="0.18034 -1.5708 0" />
    <parent
      link="base_up" />
    <child
      link="sworzen6" />
    <axis
      xyz="0 0 0" />
    <limit
      lower="-1.57"
      upper="1.57"
      effort="0"
      velocity="0" />
  </joint>
  <link
    name="ramie6">
    <inertial>
      <origin
        xyz="0.0135555483689621 0.0403021455730355 0.0249999999999963"
        rpy="0 0 0" />
      <mass
        value="0.0838871669414958" />
      <inertia
        ixx="2.06510087697225E-05"
        ixy="-5.39540654201755E-06"
        ixz="4.69626829693306E-19"
        iyy="6.4246024876452E-06"
        iyz="1.46356705373702E-18"
        izz="1.78558752997064E-05" />
    </inertial>
    <visual>
      <origin
        xyz="0 0 0"
        rpy="0 0 0" />
      <geometry>
        <mesh
          filename="package://robot_description/meshes/ramie6.STL" />
      </geometry>
      <material
        name="">
        <color
          rgba="1 0.701960784313725 0.180392156862745 1" />
      </material>
    </visual>
    <collision>
      <origin
        xyz="0 0 0"
        rpy="0 0 0" />
      <geometry>
        <mesh
          filename="package://robot_description/meshes/ramie6.STL" />
      </geometry>
    </collision>
  </link>
  <joint
    name="ramie6_joint"
    type="revolute">
    <origin
      xyz="0.028349 0 -0.099103"
      rpy="0.80073 0.76958 0.97718" />
    <parent
      link="sworzen6" />
    <child
      link="ramie6" />
    <axis
      xyz="0 0 0" />
    <limit
      lower="-1.57"
      upper="1.57"
      effort="0"
      velocity="0" />
  </joint>
  <link
    name="sworzen_ramie6">
    <inertial>
      <origin
        xyz="0.0150000000001621 0.0509887247956134 4.79130624064794E-14"
        rpy="0 0 0" />
      <mass
        value="0.0803528752062072" />
      <inertia
        ixx="1.82440179038147E-05"
        ixy="7.09453091400929E-15"
        ixz="-1.14448312506143E-15"
        iyy="4.60986798281565E-06"
        iyz="2.25784361266277E-15"
        izz="1.36341499282439E-05" />
    </inertial>
    <visual>
      <origin
        xyz="0 0 0"
        rpy="0 0 0" />
      <geometry>
        <mesh
          filename="package://robot_description/meshes/sworzen_ramie6.STL" />
      </geometry>
      <material
        name="">
        <color
          rgba="0.749019607843137 0.749019607843137 0.749019607843137 1" />
      </material>
    </visual>
    <collision>
      <origin
        xyz="0 0 0"
        rpy="0 0 0" />
      <geometry>
        <mesh
          filename="package://robot_description/meshes/sworzen_ramie6.STL" />
      </geometry>
    </collision>
  </link>
  <joint
    name="sworzen_ramie6_joint"
    type="revolute">
    <origin
      xyz="0.014217 -0.004782 0.025"
      rpy="-3.1416 -3.8441E-15 2.8171" />
    <parent
      link="ramie6" />
    <child
      link="sworzen_ramie6" />
    <axis
      xyz="0 0 0" />
    <limit
      lower="-1.57"
      upper="1.57"
      effort="0"
      velocity="0" />
  </joint>
  <link
    name="kolo6">
    <inertial>
      <origin
        xyz="0 -5.55111512312578E-16 0.0150000000000092"
        rpy="0 0 0" />
      <mass
        value="0.0407655519524368" />
      <inertia
        ixx="5.12882701567285E-31"
        ixy="7.89950323301487E-36"
        ixz="-1.50053871853581E-34"
        iyy="5.10875970381657E-31"
        iyz="3.19631892626846E-32"
        izz="2.00742764055525E-33" />
    </inertial>
    <visual>
      <origin
        xyz="0 0 0"
        rpy="0 0 0" />
      <geometry>
        <mesh
          filename="package://robot_description/meshes/kolo6.STL" />
      </geometry>
      <material
        name="">
        <color
          rgba="1 0.701960784313725 0.180392156862745 1" />
      </material>
    </visual>
    <collision>
      <origin
        xyz="0 0 0"
        rpy="0 0 0" />
      <geometry>
        <mesh
          filename="package://robot_description/meshes/kolo6.STL" />
      </geometry>
    </collision>
  </link>
  <joint
    name="kolo6_joint"
    type="continuous">
    <origin
      xyz="0.015 0.1 -0.015"
      rpy="8.743E-16 7.2164E-16 -2.1766" />
    <parent
      link="sworzen_ramie6" />
    <child
      link="kolo6" />
    <axis
      xyz="0 0 0" />
  </joint>
  <link
    name="sworzen4">
    <inertial>
      <origin
        xyz="-0.00272380950324448 0.000799447417343668 -3.86080056813398E-14"
        rpy="0 0 0" />
      <mass
        value="0.66332458707171" />
      <inertia
        ixx="1.07812831831624E-05"
        ixy="-2.87368575806907E-07"
        ixz="-1.6378861166446E-15"
        iyy="8.51479121808228E-05"
        iyz="-9.6974582904823E-15"
        izz="9.51428553890734E-05" />
    </inertial>
    <visual>
      <origin
        xyz="0 0 0"
        rpy="0 0 0" />
      <geometry>
        <mesh
          filename="package://robot_description/meshes/sworzen4.STL" />
      </geometry>
      <material
        name="">
        <color
          rgba="0.749019607843137 0.749019607843137 0.749019607843137 1" />
      </material>
    </visual>
    <collision>
      <origin
        xyz="0 0 0"
        rpy="0 0 0" />
      <geometry>
        <mesh
          filename="package://robot_description/meshes/sworzen4.STL" />
      </geometry>
    </collision>
  </link>
  <joint
    name="sworzen4_joint"
    type="revolute">
    <origin
      xyz="-0.0053809 -0.029513 0.015"
      rpy="0.18034 -1.5708 0" />
    <parent
      link="base_up" />
    <child
      link="sworzen4" />
    <axis
      xyz="0 0 0" />
    <limit
      lower="-1.57"
      upper="1.57"
      effort="0"
      velocity="0" />
  </joint>
  <link
    name="ramie4">
    <inertial>
      <origin
        xyz="-0.0238602561956144 0.0351952270010182 0.0250000000000001"
        rpy="0 0 0" />
      <mass
        value="0.0838871669414958" />
      <inertia
        ixx="1.68432477220002E-05"
        ixy="8.29349885434848E-06"
        ixz="3.34578014165449E-20"
        iyy="1.02323635353691E-05"
        iyz="-1.65462592290207E-19"
        izz="1.7855875299708E-05" />
    </inertial>
    <visual>
      <origin
        xyz="0 0 0"
        rpy="0 0 0" />
      <geometry>
        <mesh
          filename="package://robot_description/meshes/ramie4.STL" />
      </geometry>
      <material
        name="">
        <color
          rgba="1 0.701960784313725 0.180392156862745 1" />
      </material>
    </visual>
    <collision>
      <origin
        xyz="0 0 0"
        rpy="0 0 0" />
      <geometry>
        <mesh
          filename="package://robot_description/meshes/ramie4.STL" />
      </geometry>
    </collision>
  </link>
  <joint
    name="ramie4_joint"
    type="revolute">
    <origin
      xyz="-0.1 0 -0.025"
      rpy="2.38E-15 -8.0491E-16 -1.1458" />
    <parent
      link="sworzen4" />
    <child
      link="ramie4" />
    <axis
      xyz="0 0 0" />
    <limit
      lower="-1.57"
      upper="1.57"
      effort="0"
      velocity="0" />
  </joint>
  <link
    name="sworzen_ramie4">
    <inertial>
      <origin
        xyz="0.0149999999997961 0.0509887247956492 4.39093206239249E-14"
        rpy="0 0 0" />
      <mass
        value="0.0803528752062073" />
      <inertia
        ixx="1.8244017900251E-05"
        ixy="-8.54913307691169E-15"
        ixz="1.42385116114793E-15"
        iyy="4.60986798601814E-06"
        iyz="1.76347002720116E-15"
        izz="1.36341499280187E-05" />
    </inertial>
    <visual>
      <origin
        xyz="0 0 0"
        rpy="0 0 0" />
      <geometry>
        <mesh
          filename="package://robot_description/meshes/sworzen_ramie4.STL" />
      </geometry>
      <material
        name="">
        <color
          rgba="0.749019607843137 0.749019607843137 0.749019607843137 1" />
      </material>
    </visual>
    <collision>
      <origin
        xyz="0 0 0"
        rpy="0 0 0" />
      <geometry>
        <mesh
          filename="package://robot_description/meshes/sworzen_ramie4.STL" />
      </geometry>
    </collision>
  </link>
  <joint
    name="sworzen_ramie4_joint"
    type="revolute">
    <origin
      xyz="0.012416 0.0084172 0.025"
      rpy="-3.1416 -1.3711E-14 -2.5458" />
    <parent
      link="ramie4" />
    <child
      link="sworzen_ramie4" />
    <axis
      xyz="0 0 0" />
    <limit
      lower="-1.57"
      upper="1.57"
      effort="0"
      velocity="0" />
  </joint>
  <link
    name="kolo4">
    <inertial>
      <origin
        xyz="5.5511E-17 -2.2204E-16 0.015"
        rpy="0 0 0" />
      <mass
        value="0.040766" />
      <inertia
        ixx="2.3594E-32"
        ixy="6.5009E-35"
        ixz="7.0252E-34"
        iyy="2.3402E-32"
        iyz="-2.205E-33"
        izz="2.3482E-34" />
    </inertial>
    <visual>
      <origin
        xyz="0 0 0"
        rpy="0 0 0" />
      <geometry>
        <mesh
          filename="package://robot_description/meshes/kolo4.STL" />
      </geometry>
      <material
        name="">
        <color
          rgba="1 0.70196 0.18039 1" />
      </material>
    </visual>
    <collision>
      <origin
        xyz="0 0 0"
        rpy="0 0 0" />
      <geometry>
        <mesh
          filename="package://robot_description/meshes/kolo4.STL" />
      </geometry>
    </collision>
  </link>
  <joint
    name="kolo4_joint"
    type="continuous">
    <origin
      xyz="0.015 0.1 0.015"
      rpy="3.1416 3.6082E-16 -0.13282" />
    <parent
      link="sworzen_ramie4" />
    <child
      link="kolo4" />
    <axis
      xyz="0 0 0" />
  </joint>
</robot>